Successfully updated expired payments.
Successfully updated expired payments.
Successfully updated expired payments.
Successfully updated expired payments.
Successfully updated expired payments.
Successfully updated expired payments.
Successfully updated expired payments.
Successfully updated expired payments.
Successfully updated expired payments.
Successfully updated expired payments.
Successfully updated expired payments.
Successfully updated expired payments.
Successfully updated expired payments.
Successfully updated expired payments.
Successfully updated expired payments.
Successfully updated expired payments.
Successfully updated expired payments.
Successfully updated expired payments.
Successfully updated expired payments.
Successfully updated expired payments.
Successfully updated expired payments.
Successfully updated expired payments.
Successfully updated expired payments.
Successfully updated expired payments.
Successfully updated expired payments.
Successfully updated expired payments.
Successfully updated expired payments.
Successfully updated expired payments.
Successfully updated expired payments.
Traceback (most recent call last):
  File "/home/cookings/virtualenv/demologin/3.11/lib/python3.11/site-packages/pymysql/connections.py", line 803, in _write_bytes
    self._sock.sendall(data)
ConnectionResetError: [Errno 104] Connection reset by peer

During handling of the above exception, another exception occurred:

Traceback (most recent call last):
  File "/home/cookings/virtualenv/demologin/3.11/lib/python3.11/site-packages/django/db/backends/utils.py", line 105, in _execute
    return self.cursor.execute(sql, params)
           ^^^^^^^^^^^^^^^^^^^^^^^^^^^^^^^^
  File "/home/cookings/virtualenv/demologin/3.11/lib/python3.11/site-packages/django/db/backends/mysql/base.py", line 76, in execute
    return self.cursor.execute(query, args)
           ^^^^^^^^^^^^^^^^^^^^^^^^^^^^^^^^
  File "/home/cookings/virtualenv/demologin/3.11/lib/python3.11/site-packages/pymysql/cursors.py", line 153, in execute
    result = self._query(query)
             ^^^^^^^^^^^^^^^^^^
  File "/home/cookings/virtualenv/demologin/3.11/lib/python3.11/site-packages/pymysql/cursors.py", line 322, in _query
    conn.query(q)
  File "/home/cookings/virtualenv/demologin/3.11/lib/python3.11/site-packages/pymysql/connections.py", line 557, in query
    self._execute_command(COMMAND.COM_QUERY, sql)
  File "/home/cookings/virtualenv/demologin/3.11/lib/python3.11/site-packages/pymysql/connections.py", line 861, in _execute_command
    self._write_bytes(packet)
  File "/home/cookings/virtualenv/demologin/3.11/lib/python3.11/site-packages/pymysql/connections.py", line 806, in _write_bytes
    raise err.OperationalError(
pymysql.err.OperationalError: (2006, "MySQL server has gone away (ConnectionResetError(104, 'Connection reset by peer'))")

The above exception was the direct cause of the following exception:

Traceback (most recent call last):
  File "/home/cookings/demologin/manage.py", line 22, in <module>
    main()
  File "/home/cookings/demologin/manage.py", line 18, in main
    execute_from_command_line(sys.argv)
  File "/home/cookings/virtualenv/demologin/3.11/lib/python3.11/site-packages/django/core/management/__init__.py", line 442, in execute_from_command_line
    utility.execute()
  File "/home/cookings/virtualenv/demologin/3.11/lib/python3.11/site-packages/django/core/management/__init__.py", line 436, in execute
    self.fetch_command(subcommand).run_from_argv(self.argv)
  File "/home/cookings/virtualenv/demologin/3.11/lib/python3.11/site-packages/django/core/management/base.py", line 413, in run_from_argv
    self.execute(*args, **cmd_options)
  File "/home/cookings/virtualenv/demologin/3.11/lib/python3.11/site-packages/django/core/management/base.py", line 459, in execute
    output = self.handle(*args, **options)
             ^^^^^^^^^^^^^^^^^^^^^^^^^^^^^
  File "/home/cookings/demologin/demolog/management/commands/tasks.py", line 40, in handle
    schedule.run_pending()
  File "/home/cookings/virtualenv/demologin/3.11/lib/python3.11/site-packages/schedule/__init__.py", line 822, in run_pending
    default_scheduler.run_pending()
  File "/home/cookings/virtualenv/demologin/3.11/lib/python3.11/site-packages/schedule/__init__.py", line 100, in run_pending
    self._run_job(job)
  File "/home/cookings/virtualenv/demologin/3.11/lib/python3.11/site-packages/schedule/__init__.py", line 172, in _run_job
    ret = job.run()
          ^^^^^^^^^
  File "/home/cookings/virtualenv/demologin/3.11/lib/python3.11/site-packages/schedule/__init__.py", line 693, in run
    ret = self.job_func()
          ^^^^^^^^^^^^^^^
  File "/home/cookings/demologin/demolog/management/commands/tasks.py", line 15, in switch_expired_payments
    for payment in expired_payments:
  File "/home/cookings/virtualenv/demologin/3.11/lib/python3.11/site-packages/django/db/models/query.py", line 400, in __iter__
    self._fetch_all()
  File "/home/cookings/virtualenv/demologin/3.11/lib/python3.11/site-packages/django/db/models/query.py", line 1928, in _fetch_all
    self._result_cache = list(self._iterable_class(self))
                         ^^^^^^^^^^^^^^^^^^^^^^^^^^^^^^^^
  File "/home/cookings/virtualenv/demologin/3.11/lib/python3.11/site-packages/django/db/models/query.py", line 91, in __iter__
    results = compiler.execute_sql(
              ^^^^^^^^^^^^^^^^^^^^^
  File "/home/cookings/virtualenv/demologin/3.11/lib/python3.11/site-packages/django/db/models/sql/compiler.py", line 1562, in execute_sql
    cursor.execute(sql, params)
  File "/home/cookings/virtualenv/demologin/3.11/lib/python3.11/site-packages/django/db/backends/utils.py", line 122, in execute
    return super().execute(sql, params)
           ^^^^^^^^^^^^^^^^^^^^^^^^^^^^
  File "/home/cookings/virtualenv/demologin/3.11/lib/python3.11/site-packages/django/db/backends/utils.py", line 79, in execute
    return self._execute_with_wrappers(
           ^^^^^^^^^^^^^^^^^^^^^^^^^^^^
  File "/home/cookings/virtualenv/demologin/3.11/lib/python3.11/site-packages/django/db/backends/utils.py", line 92, in _execute_with_wrappers
    return executor(sql, params, many, context)
           ^^^^^^^^^^^^^^^^^^^^^^^^^^^^^^^^^^^^
  File "/home/cookings/virtualenv/demologin/3.11/lib/python3.11/site-packages/django/db/backends/utils.py", line 100, in _execute
    with self.db.wrap_database_errors:
  File "/home/cookings/virtualenv/demologin/3.11/lib/python3.11/site-packages/django/db/utils.py", line 91, in __exit__
    raise dj_exc_value.with_traceback(traceback) from exc_value
  File "/home/cookings/virtualenv/demologin/3.11/lib/python3.11/site-packages/django/db/backends/utils.py", line 105, in _execute
    return self.cursor.execute(sql, params)
           ^^^^^^^^^^^^^^^^^^^^^^^^^^^^^^^^
  File "/home/cookings/virtualenv/demologin/3.11/lib/python3.11/site-packages/django/db/backends/mysql/base.py", line 76, in execute
    return self.cursor.execute(query, args)
           ^^^^^^^^^^^^^^^^^^^^^^^^^^^^^^^^
  File "/home/cookings/virtualenv/demologin/3.11/lib/python3.11/site-packages/pymysql/cursors.py", line 153, in execute
    result = self._query(query)
             ^^^^^^^^^^^^^^^^^^
  File "/home/cookings/virtualenv/demologin/3.11/lib/python3.11/site-packages/pymysql/cursors.py", line 322, in _query
    conn.query(q)
  File "/home/cookings/virtualenv/demologin/3.11/lib/python3.11/site-packages/pymysql/connections.py", line 557, in query
    self._execute_command(COMMAND.COM_QUERY, sql)
  File "/home/cookings/virtualenv/demologin/3.11/lib/python3.11/site-packages/pymysql/connections.py", line 861, in _execute_command
    self._write_bytes(packet)
  File "/home/cookings/virtualenv/demologin/3.11/lib/python3.11/site-packages/pymysql/connections.py", line 806, in _write_bytes
    raise err.OperationalError(
django.db.utils.OperationalError: (2006, "MySQL server has gone away (ConnectionResetError(104, 'Connection reset by peer'))")
